<robot name="Work_room_door">

  <link name="base_link">
    <visual>
      <origin xyz="0 0 1.125" rpy="0 0 0" />
      <geometry>
        <cylinder length="0.2" radius="0.05"/>
      </geometry>
    </visual>
  </link>

  <link name="door">
     <inertial>
      <origin xyz="0 0 0"/> 
      <mass value="5.0" />
      <inertia  ixx="1.0" ixy="0.0"  ixz="0.0"  iyy="100.0"  iyz="0.0"  izz="1.0" />
    </inertial>
    <visual>
      <origin xyz="0 0.2 0" rpy="0 0 0" />
      <geometry>
        <box size="0.1 .4 2.2"/>
      </geometry>
    </visual>
  </link>

  <joint name="door_hinge" type="revolute">
    <parent link="base_link"/>
    <child link="door"/>
    <origin xyz="0 0 1.1"/>
    <axis xyz="0 0 1"/>
    <limit effort="15.0" lower="-1.57" upper="1.57" velocity="1"/>
  </joint>

</robot>
