<?xml version="1.0" encoding="utf-8"?>
<!-- =================================================================================== -->
<!-- |    This document was autogenerated by xacro from src/rcprg/tiago_sim_hospital/urdf/door.urdf.xacro | -->
<!-- |    EDITING THIS FILE BY HAND IS NOT RECOMMENDED                                 | -->
<!-- =================================================================================== -->
<robot name="room_door">
  <link name="base_link"/>
  <joint name="fixed" type="fixed">
    <parent link="base_link"/>
    <child link="top_post"/>
    <origin xyz="0 0 2.025"/>
  </joint>
  <link name="top_post">
    <inertial>
      <mass value="1"/>
      <inertia ixx="1.0" ixy="0.0" ixz="0.0" iyy="1.0" iyz="0.0" izz="1.0"/>
    </inertial>
    <visual>
      <origin rpy="0 0 0" xyz="0 0 0"/>
      <geometry>
        <box size="0.01 1.3 0.05"/>
      </geometry>
    </visual>
    <collision>
      <origin rpy="0 0 0" xyz="0 0 0"/>
      <geometry>
        <box size="0.01 1.3 0.05"/>
      </geometry>
    </collision>
  </link>
  <gazebo reference="top_post">
    <material>Gazebo/Black</material>
  </gazebo>
  <link name="left_post">
    <inertial>
      <mass value="1000"/>
      <inertia ixx="1.0" ixy="0.0" ixz="0.0" iyy="1.0" iyz="0.0" izz="1.0"/>
    </inertial>
    <visual>
      <origin rpy="0 0 0" xyz="0 0 0"/>
      <geometry>
        <box size="0.01 0.04 2"/>
      </geometry>
    </visual>
    <collision>
      <origin rpy="0 0 0" xyz="0 0 0"/>
      <geometry>
        <box size="0.01 0.04 2"/>
      </geometry>
    </collision>
  </link>
  <gazebo reference="left_post">
    <material>Gazebo/Black</material>
  </gazebo>
  <joint name="left_post_to_base" type="fixed">
    <parent link="top_post"/>
    <child link="left_post"/>
    <origin xyz="0 -0.63 -1.025"/>
  </joint>
  <link name="right_post">
    <inertial>
      <mass value="1000"/>
      <inertia ixx="1.0" ixy="0.0" ixz="0.0" iyy="1.0" iyz="0.0" izz="1.0"/>
    </inertial>
    <visual>
      <origin rpy="0 0 0" xyz="0 0 0"/>
      <geometry>
        <box size="0.01 0.04 2"/>
      </geometry>
    </visual>
    <collision>
      <origin rpy="0 0 0" xyz="0 0 0"/>
      <geometry>
        <box size="0.01 0.04 2"/>
      </geometry>
    </collision>
  </link>
  <gazebo reference="right_post">
    <material>Gazebo/Black</material>
  </gazebo>
  <joint name="right_post_to_base" type="fixed">
    <parent link="top_post"/>
    <child link="right_post"/>
    <origin xyz="0 0.63 -1.025"/>
  </joint>
  <link name="door_front">
    <inertial>
      <mass value="1"/>
      <inertia ixx="1.0" ixy="0.0" ixz="0.0" iyy="1.0" iyz="0.0" izz="1.0"/>
    </inertial>
    <visual>
      <origin rpy="0 0 0" xyz="-0.005 0.61 0.005"/>
      <geometry>
        <box size="0.01 1.22 1.99"/>
      </geometry>
    </visual>
    <collision>
      <origin rpy="0 0 0" xyz="-0.005 0.61 0.005"/>
      <geometry>
        <box size="0.01 1.22 1.99"/>
      </geometry>
    </collision>
  </link>
  <gazebo reference="door_front">
    <material>Gazebo/Orange</material>
  </gazebo>
  <joint name="door_front_to_left_post" type="revolute">
    <parent link="left_post"/>
    <child link="door_front"/>
    <origin xyz="0.005 0.02 0"/>
    <axis xyz="0 0 1"/>
    <limit effort="1000.0" lower="-3.14" upper="0" velocity="100"/>
    <dynamics damping=".5"/>
  </joint>
  <!--   <gazebo>
    <plugin name="gazebo_ros_control" filename="libgazebo_ros_control.so">
      <robotNamespace>/</robotNamespace>
    </plugin>
  </gazebo> -->
</robot>
